### 错误处理

Go 程序使用 error 值来表示错误状态。

与 fmt.Stringer 类似，error 类型是一个内建接口：

```go
type error interface {
    Error() string
}
```

（与 fmt.Stringer 类似，fmt 包在打印值时也会满足 error。）
通常函数会返回一个 error 值，调用的它的代码应当判断这个错误是否等于 nil 来进行错误处理。

```go
i, err := strconv.Atoi("42")
if err != nil {
    fmt.Printf("could't convert number: %v\n", err)
    return
}
fmt.Println("Converted integer:", i)
```

error 为 `nil` 时表示成功；非 `nil` 的 error 表示失败。

```go
package main

import (
	"fmt"
	"time"
)

type MyError struct {
	When time.Time
	What string
}

func (e *MyError) Error() string {
	return fmt.Sprintf("at %v, %s",
		e.When, e.What)
}

func run() error {
	return &MyError{
		time.Now(),
		"it didn't work",
	}
}

func main() {
	if err := run(); err != nil {
		fmt.Println(err)
	}
}
```

#### errors.New() 创建错误

eg:

```go
package main

import (
	"errors"
	"fmt"
)

// 自定义除法函数
func myDivide(dividend, divisor float64) (float64, error) {
	if divisor == 0 { // 除数不能为 0
		return 0, errors.New("divide by zero") // 返回一个错误
	}
	return dividend / divisor, nil
}

func main() {
	divide, err := myDivide(100, 0)
	if err != nil {
		fmt.Printf("Error: %s\n", err) // 输出错误信息
	} else {
		fmt.Printf("100 / 0 = %.2f\n", divide) // 代码执行不到这里
	}
}

// $ go run main.go
// 输出如下
/**
  Error: divide by zero
*/
```

#### fmt.Errorf() 创建错误

不同于 `errors.New()`, `fmt.Errorf()` 在构建错误时，可以进行格式化。
eg:

```go
package main

import (
	"fmt"
)

// 自定义除法函数
func myDivide(dividend, divisor float64) (float64, error) {
	if divisor == 0 { // 除数不能为 0
		return 0, fmt.Errorf("%.2f divide by zero", dividend) // 返回一个错误
	}
	return dividend / divisor, nil
}

func main() {
	divide, err := myDivide(100, 0)
	if err != nil {
		fmt.Printf("Error: %s\n", err) // 输出错误信息
	} else {
		fmt.Printf("100 / 0 = %.2f\n", divide) // 代码执行不到这里
	}
}

// $ go run main.go
// 输出如下
/**
  Error: 100.00 divide by zero
*/
```

#### 最佳实践

永远不要忽略错误，否则可能会导致程序崩溃！
